<?xml version="1.0"?>
<robot xmlns:xacro="http://www.ros.org/wiki/xacro">

    <link name="base_link">
        <visual>
            <geometry>
                <mesh filename="package://auto_tb/meshes/moborobo_short.stl" scale="1 1 1"/>
            </geometry>
        </visual>
        <collision>
            <geometry>
                <box size=".70 .470 .3"/>
            </geometry>
            <origin xyz="0 0 0.04" rpy="0 0 0" />
        </collision>
        <inertial>
            <mass value="20.0"/>
            <inertia ixx="0.51816" ixy="0" ixz="0" iyy="0.966664" iyz="0.0" izz="1.18484"/>
            <origin xyz="0 0 0.06" rpy="0 0 0" />
        </inertial>
    </link>



    <link name="front_caster_1">
        <visual>
            <geometry>
                <box size="0.05 0.05 0.05"/>
            </geometry>
            <material name="green">
                <color rgba="0.0 0.1 0.0 1"/>   
            </material>
        </visual>
        <collision>
            <geometry>
                <box size="0.05 0.05 0.05"/>
            </geometry>
        </collision>
        <inertial>
            <mass value="0.5"/>
            <inertia ixx="0.000208332" ixy="0" ixz="0" iyy="0.000208332" iyz="0.0" izz="0.000208332"/>

        </inertial>
    </link>
    <joint name="front_caster_1_joint" type="continuous">
       <axis xyz="0.0 0.0 1"/> 
       <parent link="base_link"/>
       <child link="front_caster_1"/>
       <origin xyz="-0.300 0.150 -0.130" rpy="0.0 0.0 0.0"/>
    </joint>

    <link name="front_wheel_1">
        <visual>
            <geometry>
                <cylinder radius="0.04" length="0.0228"/>
            </geometry>
            <material name="black">
                
            </material>

        </visual>
        <collision>
            <geometry>
                <cylinder radius="0.04" length="0.0228"/>
            </geometry>
        </collision>
        <inertial>
            <mass value="0.5"/>
            <inertia ixx="0.00022166" ixy="0" ixz="0" iyy="0.00022166" iyz="0.0" izz="0.0004"/>
        </inertial>
    </link>

    <joint name="front_wheel_1_joint" type="continuous">
        <axis xyz="0.0 0.0 1"/>
        <parent link="front_caster_1"/>
        <child link="front_wheel_1"/>
        <origin xyz="0.02 0.0 -0.05" rpy="-1.5708 0.0 0.0"/>
        
    </joint>



    <link name="front_caster_2">
        <visual>
            <geometry>
                <box size="0.05 0.05 0.05"/>
            </geometry>
            <material name="green">
                <color rgba="0.0 0.1 0.0 1"/>   
            </material>
        </visual>
        <collision>
            <geometry>
                <box size="0.05 0.05 0.05"/>
            </geometry>
        </collision>
        <inertial>
            <mass value="0.5"/>
            <inertia ixx="0.000208332" ixy="0" ixz="0" iyy="0.000208332" iyz="0.0" izz="0.000208332"/>
        </inertial>
    </link>
    <joint name="front_caster_2_joint" type="continuous">
       <axis xyz="0.0 0.0 1"/> 
       <parent link="base_link"/>
       <child link="front_caster_2"/>
       <origin xyz="-0.300 -0.150 -0.130" rpy="0.0 0.0 0.0"/>
    </joint>

    <link name="front_wheel_2">
        <visual>
            <geometry>
                <cylinder radius="0.04" length="0.0228"/>
            </geometry>
            <material name="black">
                
            </material>

        </visual>
        <collision>
            <geometry>
                <cylinder radius="0.04" length="0.0228"/>
            </geometry>
        </collision>
        <inertial>
            <mass value="0.5"/>
            <inertia ixx="0.00022166" ixy="0" ixz="0" iyy="0.00022166" iyz="0.0" izz="0.0004"/>
        </inertial>
    </link>

    <joint name="front_wheel_2_joint" type="continuous">
        <axis xyz="0.0 0.0 1"/>
        <parent link="front_caster_2"/>
        <child link="front_wheel_2"/>
        <origin xyz="0.02 0.0 -0.05" rpy="-1.5708 0.0 0.0"/>
        
    </joint>


    <link name="back_caster_1">
        <visual>
            <geometry>
                <box size="0.05 0.05 0.05"/>
            </geometry>
            <material name="green">
                <color rgba="0.0 0.1 0.0 1"/>   
            </material>
        </visual>
        <collision>
            <geometry>
                <box size="0.05 0.05 0.05"/>
            </geometry>
        </collision>
        <inertial>
            <mass value="0.5"/>
            <inertia ixx="0.000208332" ixy="0" ixz="0" iyy="0.000208332" iyz="0.0" izz="0.000208332"/>
        </inertial>
    </link>
    <joint name="back_caster_1_joint" type="continuous">
       <axis xyz="0.0 0.0 1"/> 
       <parent link="base_link"/>
       <child link="back_caster_1"/>
       <origin xyz="0.300 0.150 -0.130" rpy="0.0 0.0 0.0"/>
    </joint>

    <link name="back_wheel_1">
        <visual>
            <geometry>
                <cylinder radius="0.04" length="0.0228"/>
            </geometry>
            <material name="black">
                
            </material>

        </visual>
        <collision>
            <geometry>
                <cylinder radius="0.04" length="0.0228"/>
            </geometry>
        </collision>
        <inertial>
            <mass value="0.5"/>
            <inertia ixx="0.00022166" ixy="0" ixz="0" iyy="0.00022166" iyz="0.0" izz="0.0004"/>
        </inertial>
    </link>

    <joint name="back_wheel_1_joint" type="continuous">
        <axis xyz="0.0 0.0 1"/>
        <parent link="back_caster_1"/>
        <child link="back_wheel_1"/>
        <origin xyz="0.02 0.0 -0.05" rpy="-1.5708 0.0 0.0"/>
        
    </joint>



    <link name="back_caster_2">
        <visual>
            <geometry>
                <box size="0.05 0.05 0.05"/>
            </geometry>
            <material name="green">
                <color rgba="0.0 0.1 0.0 1"/>   
            </material>
        </visual>
        <collision>
            <geometry>
                <box size="0.05 0.05 0.05"/>
            </geometry>
        </collision>
        <inertial>
            <mass value="0.5"/>
            <inertia ixx="0.000208332" ixy="0" ixz="0" iyy="0.000208332" iyz="0.0" izz="0.000208332"/>
        </inertial>
    </link>
    <joint name="back_caster_2_joint" type="continuous">
       <axis xyz="0.0 0.0 1"/> 
       <parent link="base_link"/>
       <child link="back_caster_2"/>
       <origin xyz="0.300 -0.150 -0.130" rpy="0.0 0.0 0.0"/>
    </joint>

    <link name="back_wheel_2">
        <visual>
            <geometry>
                <cylinder radius="0.04" length="0.0228"/>
            </geometry>
            <material name="black">
                
            </material>

        </visual>
        <collision>
            <geometry>
                <cylinder radius="0.04" length="0.0228"/>
            </geometry>
        </collision>
        <inertial>
            <mass value="0.5"/>
            <inertia ixx="0.00022166" ixy="0" ixz="0" iyy="0.00022166" iyz="0.0" izz="0.0004"/>
        </inertial>
    </link>

    <joint name="back_wheel_2_joint" type="continuous">
        <axis xyz="0.0 0.0 1"/>
        <parent link="back_caster_2"/>
        <child link="back_wheel_2"/>
        <origin xyz="0.02 0.0 -0.05" rpy="-1.5708 0.0 0.0"/>
        
    </joint>


<link name="right_wheel">
        <visual>
            <geometry>
                <cylinder radius="0.1" length="0.04"/>
            </geometry>
            <material name="black">
                <color rgba="0.0 0.0 0.0 1"/>
            </material>

        </visual>
        <collision>
            <geometry>
                <cylinder radius="0.1" length="0.04"/>
            </geometry>
        </collision>
        <inertial>
            <mass value="2"/>
            <inertia ixx="0.005066668" ixy="0" ixz="0" iyy="0.005066668" iyz="0.0" izz="0.01"/>        </inertial>
    </link>

    <joint name="right_wheel_joint" type="continuous">
        <axis xyz="0.0 0.0 1"/>
        <parent link="base_link"/>
        <child link="right_wheel"/>
        <origin xyz="0.0 -0.175 -0.120" rpy="-1.5708 0.0 0.0"/>
        
    </joint>
    <link name="left_wheel">
        <visual>
            <geometry>
                <cylinder radius="0.1" length="0.04"/>
            </geometry>
            <material name="black">
                <color rgba="0.0 0.0 0.0 1"/>
            </material>

        </visual>
        <collision>
            <geometry>
                <cylinder radius="0.1" length="0.04"/>
            </geometry>
        </collision>
        <inertial>
            <mass value="0.5"/>
            <inertia ixx="0.001266667" ixy="0" ixz="0" iyy="0.001266667" iyz="0.0" izz="0.0025"/>        </inertial>
    </link>

    <joint name="left_wheel_joint" type="continuous">
        <axis xyz="0.0 0.0 1"/>
        <parent link="base_link"/>
        <child link="left_wheel"/>
        <origin xyz="0.0 0.175 -0.120" rpy="-1.5708 0.0 0.0"/>
        
    </joint>


    <gazebo>
        <plugin name="joint_state_publisher"
                filename="libgazebo_ros_joint_state_publisher.so">
            <jointName>front_caster_1_joint, front_wheel_1_joint, front_caster_2_joint, front_wheel_2_joint, 
                back_caster_1_joint, back_wheel_1_joint, back_caster_2_joint, back_wheel_2_joint
            </jointName>
        </plugin>
    </gazebo>

    <gazebo reference="front_caster_1">
        <material>Gazebo/White</material>
      </gazebo>
      <gazebo reference="front_wheel_1">
        <material>Gazebo/Black</material>
      </gazebo>
      <gazebo reference="front_caster_2">
        <material>Gazebo/White</material>
      </gazebo>
      <gazebo reference="front_wheel_2">
        <material>Gazebo/Black</material>
      </gazebo>
      <gazebo reference="back_caster_1">
        <material>Gazebo/White</material>
      </gazebo>
      <gazebo reference="back_wheel_1">
        <material>Gazebo/Black</material>
      </gazebo>
      <gazebo reference="back_caster_2">
        <material>Gazebo/White</material>
      </gazebo>
      <gazebo reference="back_wheel_2">
        <material>Gazebo/Black</material>
      </gazebo>
      <gazebo reference="left_wheel">
        <material>Gazebo/Black</material>
      </gazebo>
      <gazebo reference="right_wheel">
        <material>Gazebo/Black</material>
      </gazebo>




    </robot>